### Starting TaskPrologue of job 800947 on tg086 at Mon 15 Apr 2024 08:58:48 PM CEST
Running on cores 4-7,36-39 with governor ondemand
Mon Apr 15 20:58:48 2024       
+-----------------------------------------------------------------------------------------+
| NVIDIA-SMI 550.54.15              Driver Version: 550.54.15      CUDA Version: 12.4     |
|-----------------------------------------+------------------------+----------------------+
| GPU  Name                 Persistence-M | Bus-Id          Disp.A | Volatile Uncorr. ECC |
| Fan  Temp   Perf          Pwr:Usage/Cap |           Memory-Usage | GPU-Util  Compute M. |
|                                         |                        |               MIG M. |
|=========================================+========================+======================|
|   0  NVIDIA GeForce RTX 3080        On  |   00000000:3D:00.0 Off |                  N/A |
| 30%   42C    P8             11W /  300W |       1MiB /  10240MiB |      0%      Default |
|                                         |                        |                  N/A |
+-----------------------------------------+------------------------+----------------------+
                                                                                         
+-----------------------------------------------------------------------------------------+
| Processes:                                                                              |
|  GPU   GI   CI        PID   Type   Process name                              GPU Memory |
|        ID   ID                                                               Usage      |
|=========================================================================================|
|  No running processes found                                                             |
+-----------------------------------------------------------------------------------------+
### Finished TaskPrologue

/home/hpc/empk/empk004h/depression-detection/code_for_job/speech_text/bias_study
Traceback (most recent call last):
  File "/home/woody/empk/empk004h/software/private/conda/envs/venv/lib/python3.10/site-packages/urllib3/connection.py", line 198, in _new_conn
    sock = connection.create_connection(
  File "/home/woody/empk/empk004h/software/private/conda/envs/venv/lib/python3.10/site-packages/urllib3/util/connection.py", line 85, in create_connection
    raise err
  File "/home/woody/empk/empk004h/software/private/conda/envs/venv/lib/python3.10/site-packages/urllib3/util/connection.py", line 73, in create_connection
    sock.connect(sa)
TimeoutError: timed out

The above exception was the direct cause of the following exception:

Traceback (most recent call last):
  File "/home/woody/empk/empk004h/software/private/conda/envs/venv/lib/python3.10/site-packages/urllib3/connectionpool.py", line 793, in urlopen
    response = self._make_request(
  File "/home/woody/empk/empk004h/software/private/conda/envs/venv/lib/python3.10/site-packages/urllib3/connectionpool.py", line 491, in _make_request
    raise new_e
  File "/home/woody/empk/empk004h/software/private/conda/envs/venv/lib/python3.10/site-packages/urllib3/connectionpool.py", line 467, in _make_request
    self._validate_conn(conn)
  File "/home/woody/empk/empk004h/software/private/conda/envs/venv/lib/python3.10/site-packages/urllib3/connectionpool.py", line 1099, in _validate_conn
    conn.connect()
  File "/home/woody/empk/empk004h/software/private/conda/envs/venv/lib/python3.10/site-packages/urllib3/connection.py", line 616, in connect
    self.sock = sock = self._new_conn()
  File "/home/woody/empk/empk004h/software/private/conda/envs/venv/lib/python3.10/site-packages/urllib3/connection.py", line 207, in _new_conn
    raise ConnectTimeoutError(
urllib3.exceptions.ConnectTimeoutError: (<urllib3.connection.HTTPSConnection object at 0x7f4e88d85f90>, 'Connection to huggingface.co timed out. (connect timeout=10)')

The above exception was the direct cause of the following exception:

Traceback (most recent call last):
  File "/home/woody/empk/empk004h/software/private/conda/envs/venv/lib/python3.10/site-packages/requests/adapters.py", line 486, in send
    resp = conn.urlopen(
  File "/home/woody/empk/empk004h/software/private/conda/envs/venv/lib/python3.10/site-packages/urllib3/connectionpool.py", line 847, in urlopen
    retries = retries.increment(
  File "/home/woody/empk/empk004h/software/private/conda/envs/venv/lib/python3.10/site-packages/urllib3/util/retry.py", line 515, in increment
    raise MaxRetryError(_pool, url, reason) from reason  # type: ignore[arg-type]
urllib3.exceptions.MaxRetryError: HTTPSConnectionPool(host='huggingface.co', port=443): Max retries exceeded with url: /openchat/openchat-3.5-0106/resolve/main/config.json (Caused by ConnectTimeoutError(<urllib3.connection.HTTPSConnection object at 0x7f4e88d85f90>, 'Connection to huggingface.co timed out. (connect timeout=10)'))

During handling of the above exception, another exception occurred:

Traceback (most recent call last):
  File "/home/woody/empk/empk004h/software/private/conda/envs/venv/lib/python3.10/site-packages/huggingface_hub/file_download.py", line 1261, in hf_hub_download
    metadata = get_hf_file_metadata(
  File "/home/woody/empk/empk004h/software/private/conda/envs/venv/lib/python3.10/site-packages/huggingface_hub/utils/_validators.py", line 119, in _inner_fn
    return fn(*args, **kwargs)
  File "/home/woody/empk/empk004h/software/private/conda/envs/venv/lib/python3.10/site-packages/huggingface_hub/file_download.py", line 1674, in get_hf_file_metadata
    r = _request_wrapper(
  File "/home/woody/empk/empk004h/software/private/conda/envs/venv/lib/python3.10/site-packages/huggingface_hub/file_download.py", line 369, in _request_wrapper
    response = _request_wrapper(
  File "/home/woody/empk/empk004h/software/private/conda/envs/venv/lib/python3.10/site-packages/huggingface_hub/file_download.py", line 392, in _request_wrapper
    response = get_session().request(method=method, url=url, **params)
  File "/home/woody/empk/empk004h/software/private/conda/envs/venv/lib/python3.10/site-packages/requests/sessions.py", line 589, in request
    resp = self.send(prep, **send_kwargs)
  File "/home/woody/empk/empk004h/software/private/conda/envs/venv/lib/python3.10/site-packages/requests/sessions.py", line 703, in send
    r = adapter.send(request, **kwargs)
  File "/home/woody/empk/empk004h/software/private/conda/envs/venv/lib/python3.10/site-packages/huggingface_hub/utils/_http.py", line 68, in send
    return super().send(request, *args, **kwargs)
  File "/home/woody/empk/empk004h/software/private/conda/envs/venv/lib/python3.10/site-packages/requests/adapters.py", line 507, in send
    raise ConnectTimeout(e, request=request)
requests.exceptions.ConnectTimeout: (MaxRetryError("HTTPSConnectionPool(host='huggingface.co', port=443): Max retries exceeded with url: /openchat/openchat-3.5-0106/resolve/main/config.json (Caused by ConnectTimeoutError(<urllib3.connection.HTTPSConnection object at 0x7f4e88d85f90>, 'Connection to huggingface.co timed out. (connect timeout=10)'))"), '(Request ID: 1b76e9d0-c2fd-477d-a6f4-81cc7f9a9525)')

The above exception was the direct cause of the following exception:

Traceback (most recent call last):
  File "/home/woody/empk/empk004h/software/private/conda/envs/venv/lib/python3.10/site-packages/transformers/utils/hub.py", line 398, in cached_file
    resolved_file = hf_hub_download(
  File "/home/woody/empk/empk004h/software/private/conda/envs/venv/lib/python3.10/site-packages/huggingface_hub/utils/_validators.py", line 119, in _inner_fn
    return fn(*args, **kwargs)
  File "/home/woody/empk/empk004h/software/private/conda/envs/venv/lib/python3.10/site-packages/huggingface_hub/file_download.py", line 1406, in hf_hub_download
    raise LocalEntryNotFoundError(
huggingface_hub.utils._errors.LocalEntryNotFoundError: An error happened while trying to locate the file on the Hub and we cannot find the requested files in the local cache. Please check your connection and try again or make sure your Internet connection is on.

The above exception was the direct cause of the following exception:

Traceback (most recent call last):
  File "/home/hpc/empk/empk004h/depression-detection/code_for_job/speech_text/bias_study/test_gpu_exist.py", line 42, in <module>
    guidance = load_model_and_tokenizer("openchat/openchat-3.5-0106", bnb_config, n_gpus, max_memory, token)
  File "/home/hpc/empk/empk004h/depression-detection/code_for_job/speech_text/bias_study/test_gpu_exist.py", line 19, in load_model_and_tokenizer
    model = AutoModelForCausalLM.from_pretrained(
  File "/home/woody/empk/empk004h/software/private/conda/envs/venv/lib/python3.10/site-packages/transformers/models/auto/auto_factory.py", line 523, in from_pretrained
    config, kwargs = AutoConfig.from_pretrained(
  File "/home/woody/empk/empk004h/software/private/conda/envs/venv/lib/python3.10/site-packages/transformers/models/auto/configuration_auto.py", line 1138, in from_pretrained
    config_dict, unused_kwargs = PretrainedConfig.get_config_dict(pretrained_model_name_or_path, **kwargs)
  File "/home/woody/empk/empk004h/software/private/conda/envs/venv/lib/python3.10/site-packages/transformers/configuration_utils.py", line 631, in get_config_dict
    config_dict, kwargs = cls._get_config_dict(pretrained_model_name_or_path, **kwargs)
  File "/home/woody/empk/empk004h/software/private/conda/envs/venv/lib/python3.10/site-packages/transformers/configuration_utils.py", line 686, in _get_config_dict
    resolved_config_file = cached_file(
  File "/home/woody/empk/empk004h/software/private/conda/envs/venv/lib/python3.10/site-packages/transformers/utils/hub.py", line 441, in cached_file
    raise EnvironmentError(
OSError: We couldn't connect to 'https://huggingface.co' to load this file, couldn't find it in the cached files and it looks like openchat/openchat-3.5-0106 is not the path to a directory containing a file named config.json.
Checkout your internet connection or see how to run the library in offline mode at 'https://huggingface.co/docs/transformers/installation#offline-mode'.
srun: error: tg086: task 0: Exited with exit code 1
srun: Terminating StepId=800947.0
=== JOB_STATISTICS ===
=== current date     : Mon 15 Apr 2024 09:02:55 PM CEST
= Job-ID             : 800947 on tinygpu
= Job-Name           : test_gpu_exist.sh
= Job-Command        : /home/hpc/empk/empk004h/depression-detection/code_for_job/speech_text/bias_study/test_gpu_exist.sh
= Initial workdir    : /home/hpc/empk/empk004h/depression-detection/code_for_job/speech_text/bias_study
= Queue/Partition    : rtx3080
= Slurm account      : empk with QOS=normal
= Requested resources:  for 10:00:00
= Elapsed runtime    : 00:04:08
= Total RAM usage    : 0.2 GiB of requested  GiB (%)   
= Node list          : tg086
= Subm/Elig/Start/End: 2024-04-15T20:58:47 / 2024-04-15T20:58:47 / 2024-04-15T20:58:47 / 2024-04-15T21:02:55
======================
=== Quota infos ======
    Path              Used     SoftQ    HardQ    Gracetime  Filec    FileQ    FiHaQ    FileGrace    
    /home/hpc           51.2G   104.9G   209.7G        N/A  19,430      500K   1,000K        N/A    
    /home/vault       2303.5G     0.0K     0.0K        N/A      86K     300K     450K        N/A    
======================
=== GPU utilization ==
gpu_name, gpu_bus_id, pid, gpu_utilization [%], mem_utilization [%], max_memory_usage [MiB], time [ms]
